Workbook
Name Slicer_Application_Status: #N/A
Name Slicer_Month: #N/A
Name Slicer_Year1: #N/A

Sheet Overview
I3: Total Financing | K3: Total Amount Paid | M3: Outstanding Balance | O3: Interest Income
I4: ='Analysis - financing'!I10 -> 117619700
I5: ='Analysis - financing'!$O$7 -> 979710200 | J5: ='Analysis - financing'!$AE$7 -> 117619700
I6: =IF('Analysis - financing'!$Z$8>0,"▲ "&TEXT('Analysis - financing'!$Z$8,"0.0%"),IF('Analysis - financing'!Z8<0,"▼ "&TEXT(ABS('Analysis - financing'!$Z$8),"0.0%"),"— 0.0%")) -> ▼ 16.9%
D14: Line Chart

Sheet Application
I3: Total Applications | K3: Approved Application | M3: Approval Rate | O3: Rejection Rate
D14: Line Chart

Sheet Insight

Sheet Analysis - financing
C2: =TODAY() -> 46270
C4: ="DATA AS OF "&TEXT(MAX(tbl_LoanData[Application Date]),"mmm d, yyyy") -> DATA AS OF Aug 25, 2026 | J4: ='Analysis - financing'!CD15 -> 0.76047904
AD5: Total Financing
O6: Look Up for last YTD | T6: Total Financing Look Up for last MTD | Y6: Total Financing | Z6: Table Helper | AD6: Look Up for last MTD
O7: =LOOKUP(9.99999999999999E+307,Q17:Q1000) -> 979710200 | T7: =LOOKUP(9.99999999999999E+307,U17:U1000) -> 83659000 | Y7: Previous MoM% | AD7: =LOOKUP(9.99999999999999E+307,AD17:AD1000) -> 46204 | AE7: =LOOKUP(9.99999999999999E+307,AE17:AE1000) -> 117619700 | BU7: Total Applications | BV7: =SUM(BV14:BV500) -> 1364 | BY7: Total Approved Application | BZ7: =SUM(BZ14:BZ500) -> 127
Y8: =AD7 -> 46204 | Z8: =INDEX(AA16:AA72,MATCH($AD$7,Y16:Y72,0)) -> -0.16852151 | BY8: Approval Rate | BZ8: =BZ7/BV7 -> 0.093108504
I9: Total Financing | J9: Total Amount Paid | K9: Outstanding Balance | L9: Intrest Income | BY9: Rejection Rate
I10: =SUM(I17:I25) -> 117619700 | J10: =SUM(J17:J25) -> 966456.05 | K10: =SUM(K17:K25) -> 1.5346928e+08 | L10: =SUM(L17:L25) -> 36816037
BU12: Application Count | BY12: Application Status | BZ12: Approved
O13: Application Status | P13: Approved
C14: Application Status | D14: Approved | H14: Application Status | I14: Approved | O14: Year | P14: 2026 | T14: Application Status | U14: Approved | Y14: Application Status | Z14: Approved | AD14: Application Status | AE14: Approved | AM14: Application Status | AN14: Approved | AR14: Application Status | AS14: Approved | AW14: Application Status | AX14: Approved | BB14: Application Status | BC14: Approved | BG14: Application Status | BH14: Approved | BL14: Application Status | BM14: Approved | BP14: Application Status | BQ14: Approved | BU14: Date | BV14: Count of Application Status | BW14: Sum of Approved Helper | BY14: Date | BZ14: Approved Application | CC14: Status | CD14: Status Percentage | CG14: Status | CH14: Count of Age Bracket
BU15: 46023 | BV15: 194 | BW15: 149 | BY15: 46204 | BZ15: 127 | CC15: Approved | CD15: 0.76047904 | CG15: 18-24 | CH15: 11
C16: Sum of Loan Amount | D16: Approved Customers | E16: Average of Loan amount | H16: Row Labels | I16: Sum of Loan Amount | J16: Sum of Amount Paid | K16: Sum of Outstanding Balance | L16: Sum of Interest Income | O16: Date | P16: Sum of Loan Amount | Q16: Running Total In | T16: Date | U16: Total Loans | Y16: Date | Z16: Total Loans | AA16: MoM% | AD16: Date | AE16: Total Loans | AI16: Status | AJ16: Customers | AM16: Status | AN16: Customers | AR16: Brand | AS16: Total Approved Amount | AW16: Branch | AX16: Total Approved Amount | BB16: Vehicle Type | BC16: Total Approved Amount | BG16: Vehicle Type | BH16: Count of Vehicle Type | BL16: Gender | BM16: Count of Gender | BP16: Loan Status | BQ16: Count of Loan Status | BU16: 46054 | BV16: 147 | BW16: 115 | CC16: Pending | CD16: 0.10778443 | CG16: 25-34 | CH16: 34
C17: 117619700 | D17: 127 | E17: 926139.37 | H17: 2026 | I17: 117619700 | J17: 966456.05 | K17: 1.5346928e+08 | L17: 36816037 | O17: January | P17: 151982000 | Q17: 151982000 | T17: 46023 | U17: 151982000 | Y17: 44927 | Z17: 135232300 | AD17: 46204 | AE17: 117619700 | AI17: Low Risk | AJ17: 125 | AM17: Medium RIsk | AN17: 0.015748031 | AR17: Toyota | AS17: 23155300 | AW17: Davao | AX17: 12114300 | BB17: Motorcycle | BC17: 2316700 | BG17: Truck | BH17: 2 | BL17: Female | BM17: 0.43307087 | BP17: Active | BQ17: 1 | BU17: 46082 | BV17: 174 | BW17: 129 | CC17: Rejected | CD17: 0.13173653 | CG17: 35-44 | CH17: 31
O18: February | P18: 108741100 | Q18: 260723100 | T18: 46054 | U18: 108741100 | Y18: 44958 | Z18: 133372100 | AA18: -0.013755589 | AI18: Not Applicable | AJ18: 40 | AM18: Low Risk | AN18: 0.98425197 | AR18: Honda | AS18: 22997400 | AW18: Makati | AX18: 12371500 | BB18: Truck | BC18: 5306700 | BG18: Pickup | BH18: 14 | BL18: Male | BM18: 0.56692913 | BU18: 46113 | BV18: 167 | BW18: 132 | CG18: 45-54 | CH18: 43
O19: March | P19: 113040900 | Q19: 373764000 | T19: 46082 | U19: 113040900 | Y19: 44986 | Z19: 145709500 | AA19: 0.092503605 | AI19: Medium RIsk | AJ19: 2 | AR19: Ford | AS19: 14031400 | AW19: Cavite | AX19: 12663300 | BB19: Pickup | BC19: 16518800 | BG19: Motorcycle | BH19: 22 | BU19: 46143 | BV19: 163 | BW19: 124 | CG19: 55-64 | CH19: 43
O20: April | P20: 135152900 | Q20: 508916900 | T20: 46113 | U20: 135152900 | Y20: 45017 | Z20: 133028600 | AA20: -0.087028643 | AR20: Mitsubishi | AS20: 13951500 | AW20: Quezon City | AX20: 15846700 | BB20: Sedan | BC20: 26779300 | BG20: SUV | BH20: 28 | BU20: 46174 | BV20: 187 | BW20: 145 | CG20: 65+ | CH20: 5
O21: May | P21: 128056100 | Q21: 636973000 | T21: 46143 | U21: 128056100 | Y21: 45047 | Z21: 132813100 | AA21: -0.0016199524 | AI21: Total | AJ21: =SUM(AJ17:AJ20) -> 167 | AR21: Hyundai | AS21: 11061700 | AW21: CDO | AX21: 17831100 | BB21: MPV/Van | BC21: 29972500 | BG21: MPV/Van | BH21: 29 | BU21: 46204 | BV21: 167 | BW21: 127
O22: June | P22: 141458500 | Q22: 778431500 | T22: 46174 | U22: 141458500 | Y22: 45078 | Z22: 120023500 | AA22: -0.09629773 | AR22: Nissan | AS22: 10178100 | BB22: SUV | BC22: 36725700 | BG22: Sedan | BH22: 32 | BU22: 46235 | BV22: 165 | BW22: 125
O23: July | P23: 117619700 | Q23: 896051200 | T23: 46204 | U23: 117619700 | Y23: 45108 | Z23: 136643400 | AA23: 0.13847205 | AR23: Isuzu | AS23: 8442900
O24: August | P24: 83659000 | Q24: 979710200 | T24: 46235 | U24: 83659000 | Y24: 45139 | Z24: 147659900 | AA24: 0.080622262 | AR24: Suzuki | AS24: 6877900
Y25: 45170 | Z25: 141300400 | AA25: -0.043068565 | AR25: Kia | AS25: 3822100
Y26: 45200 | Z26: 160190700 | AA26: 0.13368894 | AR26: Hino | AS26: 1788200
Y27: 45231 | Z27: 120250500 | AA27: -0.24932908 | AR27: Yamaha | AS27: 936600
Y28: 45261 | Z28: 171109600 | AA28: 0.42294294 | AR28: Kawasaki | AS28: 376600
Y29: 45292 | Z29: 113893500 | AA29: -0.33438276
Y30: 45323 | Z30: 119264800 | AA30: 0.047160725
Y31: 45352 | Z31: 139185400 | AA31: 0.16702833
Y32: 45383 | Z32: 138592100 | AA32: -0.0042626597
Y33: 45413 | Z33: 134241000 | AA33: -0.031395007
Y34: 45444 | Z34: 157307100 | AA34: 0.17182604
Y35: 45474 | Z35: 141233900 | AA35: -0.10217721
Y36: 45505 | Z36: 129620300 | AA36: -0.08222955
Y37: 45536 | Z37: 117633200 | AA37: -0.09247857
Y38: 45566 | Z38: 128555300 | AA38: 0.092848788
Y39: 45597 | Z39: 140079300 | AA39: 0.089642356
Y40: 45627 | Z40: 119047700 | AA40: -0.15014067
... Y60: 46235 | Z60: 83659000 | AA60: -0.28873309

Sheet Loan Data
A1: Loan ID | B1: Customer ID | C1: First Name | D1: Middle Name | E1: Last Name | F1: Age | G1: Gender | H1: City | I1: Region | J1: Application Date | K1: Approval Date | L1: Vehicle Type | M1: Vehicle Brand | N1: Vehicle Model | O1: Vehicle Price | P1: Down Payment | Q1: Loan Amount | R1: Loan Term (Months) | S1: Interest Rate (%) | T1: Monthly Amortization | U1: Application Status | V1: Loan Status | W1: Amount Paid | X1: Outstanding Balance | Y1: Target Amount | Z1: Days Past Due | AA1: Delinquency Status | AB1: Branch | AC1: Loan Officer / Collector | AD1: Payment Frequency | AE1: Loan-to-Value (%) | AF1: Missed Payments (Count) | AG1: Risk Category | AH1: Approval Turnaround (Days) | AI1: Age Bracket | AJ1: Year | AK1: Month | AL1: First Day of the Month | AM1: MTD Amount | AN1: Interest Income | AO1: Approved Helper | AP1: MTD Period | AQ1: MTD Date Range
A2: LN-100006 | B2: CUS-200006 | C2: Angela | D2: Villanueva | E2: Manalo | F2: 25 | G2: Female | H2: Vigan | I2: Region I (Ilocos Region) | J2: 44928 | K2: 44935 | L2: Pickup | M2: Ford | N2: Ranger | O2: 1477000 | P2: 172700 | Q2: 1304300 | R2: 48 | S2: 5.75 | T2: 33422.69 | U2: Approved | V2: Active | W2: 1270062.2 | X2: 334226.78 | Y2: 1604289 | Z2: 145 | AA2: Over 90 Days | AB2: Makati | AC2: J. Espino | AD2: Monthly | AE2: 88.31 | AF2: 5 | AG2: High Risk | AH2: 7 | AI2: =IF(F2<25,"18-24",IF(F2<35,"25-34",IF(F2<45,"35-44",IF(F2<55,"45-54",IF(F2<65,"55-64","65+"))))) -> 25-34 | AJ2: =YEAR(tbl_LoanData[[#This Row],[Application Date]]) -> 2023 | AK2: =TEXT(tbl_LoanData[[#This Row],[Application Date]],"MMMM") -> January | AL2: =DATE(YEAR(tbl_LoanData[[#This Row],[Application Date]]),MONTH(tbl_LoanData[[#This Row],[Application Date]]),1) -> 44927 | AM2: =IF(AND(tbl_LoanData[[#This Row],[Application Date]]>=EOMONTH(TODAY(),-1)+1,tbl_LoanData[[#This Row],[Application Date]]<=TODAY()),tbl_LoanData[[#This Row],[Loan Amount]],0) -> 0 | AN2: =tbl_LoanData[[#This Row],[Amount Paid]]-(Q2-X2) -> 299989 | AO2: =IF(tbl_LoanData[[#This Row],[Application Status]]="Approved",1,0) -> 1 | AP2: =IF(AND(J2>=DATE(YEAR(TODAY()),MONTH(TODAY()),1),J2<=TODAY()),"Current MTD",IF(AND(J2>=EOMONTH(TODAY(),-2)+1,J2<=EOMONTH(TODAY(),-1)),"Previous MTD","")) | AQ2: =IF(AND(J2>=DATE(YEAR(TODAY()),MONTH(TODAY()),1),J2<=TODAY()),TEXT(DATE(YEAR(TODAY()),MONTH(TODAY()),1),"mmm d")&"–"&DAY(TODAY()),IF(AND(J2>=EOMONTH(TODAY(),-2)+1,J2<=EOMONTH(TODAY(),-1)),""&TEXT(EOMONTH(TODAY(),-2)+1,"mmm d")&"–"&DAY(TODAY()),""))
A3: LN-100117 | B3: CUS-200117 | C3: Camille | D3: Santos | E3: Umali | F3: 58 | G3: Female | H3: Lucena | I3: Region IV-A (CALABARZON) | J3: 44928 | K3: 44937 | L3: SUV | M3: Mitsubishi | N3: Xpander Cross | O3: 2055000 | P3: 637500 | Q3: 1417500 | R3: 60 | S3: 6 | T3: 30712.5 | U3: Approved | V3: Active | W3: 1320637.5 | X3: 522112.5 | Y3: 1842750 | Z3: 0 | AA3: Current | AB3: Manila | AC3: D. Morales | AD3: Monthly | AE3: 68.98 | AF3: 0 | AG3: Low Risk | AH3: 9 | AI3: =IF(F3<25,"18-24",IF(F3<35,"25-34",IF(F3<45,"35-44",IF(F3<55,"45-54",IF(F3<65,"55-64","65+"))))) -> 55-64 | AJ3: =YEAR(tbl_LoanData[[#This Row],[Application Date]]) -> 2023 | AK3: =TEXT(tbl_LoanData[[#This Row],[Application Date]],"MMMM") -> January | AL3: =DATE(YEAR(tbl_LoanData[[#This Row],[Application Date]]),MONTH(tbl_LoanData[[#This Row],[Application Date]]),1) -> 44927 | AM3: =IF(AND(tbl_LoanData[[#This Row],[Application Date]]>=EOMONTH(TODAY(),-1)+1,tbl_LoanData[[#This Row],[Application Date]]<=TODAY()),tbl_LoanData[[#This Row],[Loan Amount]],0) -> 0 | AN3: =tbl_LoanData[[#This Row],[Amount Paid]]-(Q3-X3) -> 425250 | AO3: =IF(tbl_LoanData[[#This Row],[Application Status]]="Approved",1,0) -> 1 | AP3: =IF(AND(J3>=DATE(YEAR(TODAY()),MONTH(TODAY()),1),J3<=TODAY()),"Current MTD",IF(AND(J3>=EOMONTH(TODAY(),-2)+1,J3<=EOMONTH(TODAY(),-1)),"Previous MTD","")) | AQ3: =IF(AND(J3>=DATE(YEAR(TODAY()),MONTH(TODAY()),1),J3<=TODAY()),TEXT(DATE(YEAR(TODAY()),MONTH(TODAY()),1),"mmm d")&"–"&DAY(TODAY()),IF(AND(J3>=EOMONTH(TODAY(),-2)+1,J3<=EOMONTH(TODAY(),-1)),""&TEXT(EOMONTH(TODAY(),-2)+1,"mmm d")&"–"&DAY(TODAY()),""))
A4: LN-100160 | B4: CUS-200160 | C4: Ricardo | D4: Salazar | E4: Quiambao | F4: 57 | G4: Male | H4: Batangas City | I4: Region IV-A (CALABARZON) | J4: 44940 | K4: 44951 | L4: SUV | M4: Honda | N4: BR-V | O4: 1996000 | P4: 266400 | Q4: 1729600 | R4: 12 | S4: 6.05 | T4: 152853.4 | U4: Approved | V4: Defaulted | W4: 1681387.4 | X4: 152853.4 | Y4: 1834240.8 | Z4: 30 | AA4: 1-30 Days | AB4: CDO | AC4: I. Cabrera | AD4: Monthly | AE4: 86.65 | AF4: 1 | AG4: Low Risk | AH4: 11 | AI4: =IF(F4<25,"18-24",IF(F4<35,"25-34",IF(F4<45,"35-44",IF(F4<55,"45-54",IF(F4<65,"55-64","65+"))))) -> 55-64 | AJ4: =YEAR(tbl_LoanData[[#This Row],[Application Date]]) -> 2023 | AK4: =TEXT(tbl_LoanData[[#This Row],[Application Date]],"MMMM") -> January | AL4: =DATE(YEAR(tbl_LoanData[[#This Row],[Application Date]]),MONTH(tbl_LoanData[[#This Row],[Application Date]]),1) -> 44927 | AM4: =IF(AND(tbl_LoanData[[#This Row],[Application Date]]>=EOMONTH(TODAY(),-1)+1,tbl_LoanData[[#This Row],[Application Date]]<=TODAY()),tbl_LoanData[[#This Row],[Loan Amount]],0) -> 0 | AN4: =tbl_LoanData[[#This Row],[Amount Paid]]-(Q4-X4) -> 104640.8 | AO4: =IF(tbl_LoanData[[#This Row],[Application Status]]="Approved",1,0) -> 1 | AP4: =IF(AND(J4>=DATE(YEAR(TODAY()),MONTH(TODAY()),1),J4<=TODAY()),"Current MTD",IF(AND(J4>=EOMONTH(TODAY(),-2)+1,J4<=EOMONTH(TODAY(),-1)),"Previous MTD","")) | AQ4: =IF(AND(J4>=DATE(YEAR(TODAY()),MONTH(TODAY()),1),J4<=TODAY()),TEXT(DATE(YEAR(TODAY()),MONTH(TODAY()),1),"mmm d")&"–"&DAY(TODAY()),IF(AND(J4>=EOMONTH(TODAY(),-2)+1,J4<=EOMONTH(TODAY(),-1)),""&TEXT(EOMONTH(TODAY(),-2)+1,"mmm d")&"–"&DAY(TODAY()),""))
A5: LN-100217 | B5: CUS-200217 | C5: Rodel | D5: Ocampo | E5: Pascual | F5: 31 | G5: Male | H5: Malolos | I5: Region III (Central Luzon) | J5: 44952 | K5: 44959 | L5: SUV | M5: Kia | N5: Sportage | O5: 1936000 | P5: 746800 | Q5: 1189200 | R5: 36 | S5: 14.47 | T5: 47373.1 | U5: Approved | V5: Closed - Fully Paid | W5: 1705431.7 | X5: 0 | Y5: 1705431.7 | Z5: 0 | AA5: Current | AB5: Makati | AC5: D. Morales | AD5: Monthly | AE5: 61.43 | AF5: 0 | AG5: Low Risk | AH5: 7 | AI5: =IF(F5<25,"18-24",IF(F5<35,"25-34",IF(F5<45,"35-44",IF(F5<55,"45-54",IF(F5<65,"55-64","65+"))))) -> 25-34 | AJ5: =YEAR(tbl_LoanData[[#This Row],[Application Date]]) -> 2023 | AK5: =TEXT(tbl_LoanData[[#This Row],[Application Date]],"MMMM") -> January | AL5: =DATE(YEAR(tbl_LoanData[[#This Row],[Application Date]]),MONTH(tbl_LoanData[[#This Row],[Application Date]]),1) -> 44927 | AM5: =IF(AND(tbl_LoanData[[#This Row],[Application Date]]>=EOMONTH(TODAY(),-1)+1,tbl_LoanData[[#This Row],[Application Date]]<=TODAY()),tbl_LoanData[[#This Row],[Loan Amount]],0) -> 0 | AN5: =tbl_LoanData[[#This Row],[Amount Paid]]-(Q5-X5) -> 516231.72 | AO5: =IF(tbl_LoanData[[#This Row],[Application Status]]="Approved",1,0) -> 1 | AP5: =IF(AND(J5>=DATE(YEAR(TODAY()),MONTH(TODAY()),1),J5<=TODAY()),"Current MTD",IF(AND(J5>=EOMONTH(TODAY(),-2)+1,J5<=EOMONTH(TODAY(),-1)),"Previous MTD","")) | AQ5: =IF(AND(J5>=DATE(YEAR(TODAY()),MONTH(TODAY()),1),J5<=TODAY()),TEXT(DATE(YEAR(TODAY()),MONTH(TODAY()),1),"mmm d")&"–"&DAY(TODAY()),IF(AND(J5>=EOMONTH(TODAY(),-2)+1,J5<=EOMONTH(TODAY(),-1)),""&TEXT(EOMONTH(TODAY(),-2)+1,"mmm d")&"–"&DAY(TODAY()),""))
A6: LN-100228 | B6: CUS-200228 | C6: Analyn | D6: Castillo | E6: Marquez | F6: 33 | G6: Female | H6: Caloocan | I6: NCR | J6: 44953 | K6: 44974 | L6: Pickup | M6: Nissan | N6: Navara | O6: 1382000 | P6: 182700 | Q6: 1199300 | R6: 36 | S6: 14.03 | T6: 47335.7 | U6: Approved | V6: Closed - Fully Paid | W6: 1704085.4 | X6: 0 | Y6: 1704085.4 | Z6: 0 | AA6: Current | AB6: Pampanga | AC6: H. Isip | AD6: Monthly | AE6: 86.78 | AF6: 0 | AG6: Low Risk | AH6: 21 | AI6: =IF(F6<25,"18-24",IF(F6<35,"25-34",IF(F6<45,"35-44",IF(F6<55,"45-54",IF(F6<65,"55-64","65+"))))) -> 25-34 | AJ6: =YEAR(tbl_LoanData[[#This Row],[Application Date]]) -> 2023 | AK6: =TEXT(tbl_LoanData[[#This Row],[Application Date]],"MMMM") -> January | AL6: =DATE(YEAR(tbl_LoanData[[#This Row],[Application Date]]),MONTH(tbl_LoanData[[#This Row],[Application Date]]),1) -> 44927 | AM6: =IF(AND(tbl_LoanData[[#This Row],[Application Date]]>=EOMONTH(TODAY(),-1)+1,tbl_LoanData[[#This Row],[Application Date]]<=TODAY()),tbl_LoanData[[#This Row],[Loan Amount]],0) -> 0 | AN6: =tbl_LoanData[[#This Row],[Amount Paid]]-(Q6-X6) -> 504785.37 | AO6: =IF(tbl_LoanData[[#This Row],[Application Status]]="Approved",1,0) -> 1 | AP6: =IF(AND(J6>=DATE(YEAR(TODAY()),MONTH(TODAY()),1),J6<=TODAY()),"Current MTD",IF(AND(J6>=EOMONTH(TODAY(),-2)+1,J6<=EOMONTH(TODAY(),-1)),"Previous MTD","")) | AQ6: =IF(AND(J6>=DATE(YEAR(TODAY()),MONTH(TODAY()),1),J6<=TODAY()),TEXT(DATE(YEAR(TODAY()),MONTH(TODAY()),1),"mmm d")&"–"&DAY(TODAY()),IF(AND(J6>=EOMONTH(TODAY(),-2)+1,J6<=EOMONTH(TODAY(),-1)),""&TEXT(EOMONTH(TODAY(),-2)+1,"mmm d")&"–"&DAY(TODAY()),""))
A7: LN-100253 | B7: CUS-200253 | C7: Vicente | D7: Fernandez | E7: Sarmiento | F7: 23 | G7: Male | H7: San Pablo | I7: Region IV-A (CALABARZON) | J7: 44957 | K7: 44972 | L7: Sedan | M7: Hyundai | N7: Elantra | O7: 1208000 | P7: 361400 | Q7: 846600 | R7: 36 | S7: 14.33 | T7: 33626.48 | U7: Approved | V7: Closed - Fully Paid | W7: 1210553.3 | X7: 0 | Y7: 1210553.3 | Z7: 0 | AA7: Current | AB7: Makati | AC7: J. Espino | AD7: Monthly | AE7: 70.08 | AF7: 0 | AG7: Low Risk | AH7: 15 | AI7: =IF(F7<25,"18-24",IF(F7<35,"25-34",IF(F7<45,"35-44",IF(F7<55,"45-54",IF(F7<65,"55-64","65+"))))) -> 18-24 | AJ7: =YEAR(tbl_LoanData[[#This Row],[Application Date]]) -> 2023 | AK7: =TEXT(tbl_LoanData[[#This Row],[Application Date]],"MMMM") -> January | AL7: =DATE(YEAR(tbl_LoanData[[#This Row],[Application Date]]),MONTH(tbl_LoanData[[#This Row],[Application Date]]),1) -> 44927 | AM7: =IF(AND(tbl_LoanData[[#This Row],[Application Date]]>=EOMONTH(TODAY(),-1)+1,tbl_LoanData[[#This Row],[Application Date]]<=TODAY()),tbl_LoanData[[#This Row],[Loan Amount]],0) -> 0 | AN7: =tbl_LoanData[[#This Row],[Amount Paid]]-(Q7-X7) -> 363953.34 | AO7: =IF(tbl_LoanData[[#This Row],[Application Status]]="Approved",1,0) -> 1 | AP7: =IF(AND(J7>=DATE(YEAR(TODAY()),MONTH(TODAY()),1),J7<=TODAY()),"Current MTD",IF(AND(J7>=EOMONTH(TODAY(),-2)+1,J7<=EOMONTH(TODAY(),-1)),"Previous MTD","")) | AQ7: =IF(AND(J7>=DATE(YEAR(TODAY()),MONTH(TODAY()),1),J7<=TODAY()),TEXT(DATE(YEAR(TODAY()),MONTH(TODAY()),1),"mmm d")&"–"&DAY(TODAY()),IF(AND(J7>=EOMONTH(TODAY(),-2)+1,J7<=EOMONTH(TODAY(),-1)),""&TEXT(EOMONTH(TODAY(),-2)+1,"mmm d")&"–"&DAY(TODAY()),""))
A8: LN-100310 | B8: CUS-200310 | C8: Roberto | D8: Salazar | E8: Quiambao | F8: 38 | G8: Male | H8: Iloilo City | I8: Region VI (Western Visayas) | J8: 44951 | L8: Truck | M8: Fuso | N8: Canter | O8: 3233000 | P8: 387000 | Q8: 2846000 | R8: 24 | S8: 14.5 | T8: 152972.5 | U8: Rejected | V8: Not Applicable | W8: 0 | X8: 0 | Y8: 3671340 | Z8: 0 | AA8: Not Applicable | AB8: Pampanga | AC8: D. Morales | AD8: Monthly | AE8: 88.03 | AF8: 0 | AG8: Not Applicable | AI8: =IF(F8<25,"18-24",IF(F8<35,"25-34",IF(F8<45,"35-44",IF(F8<55,"45-54",IF(F8<65,"55-64","65+"))))) -> 35-44 | AJ8: =YEAR(tbl_LoanData[[#This Row],[Application Date]]) -> 2023 | AK8: =TEXT(tbl_LoanData[[#This Row],[Application Date]],"MMMM") -> January | AL8: =DATE(YEAR(tbl_LoanData[[#This Row],[Application Date]]),MONTH(tbl_LoanData[[#This Row],[Application Date]]),1) -> 44927 | AM8: =IF(AND(tbl_LoanData[[#This Row],[Application Date]]>=EOMONTH(TODAY(),-1)+1,tbl_LoanData[[#This Row],[Application Date]]<=TODAY()),tbl_LoanData[[#This Row],[Loan Amount]],0) -> 0 | AN8: =tbl_LoanData[[#This Row],[Amount Paid]]-(Q8-X8) -> -2846000 | AO8: =IF(tbl_LoanData[[#This Row],[Application Status]]="Approved",1,0) -> 0 | AP8: =IF(AND(J8>=DATE(YEAR(TODAY()),MONTH(TODAY()),1),J8<=TODAY()),"Current MTD",IF(AND(J8>=EOMONTH(TODAY(),-2)+1,J8<=EOMONTH(TODAY(),-1)),"Previous MTD","")) | AQ8: =IF(AND(J8>=DATE(YEAR(TODAY()),MONTH(TODAY()),1),J8<=TODAY()),TEXT(DATE(YEAR(TODAY()),MONTH(TODAY()),1),"mmm d")&"–"&DAY(TODAY()),IF(AND(J8>=EOMONTH(TODAY(),-2)+1,J8<=EOMONTH(TODAY(),-1)),""&TEXT(EOMONTH(TODAY(),-2)+1,"mmm d")&"–"&DAY(TODAY()),""))
A9: LN-100343 | B9: CUS-200343 | C9: Cristina | D9: Cruz | E9: Guevarra | F9: 24 | G9: Female | H9: Lucena | I9: Region IV-A (CALABARZON) | J9: 44951 | L9: Pickup | M9: Nissan | N9: Navara | O9: 1652000 | P9: 561500 | Q9: 1090500 | R9: 36 | S9: 13.59 | T9: 42641.58 | U9: Rejected | V9: Not Applicable | W9: 0 | X9: 0 | Y9: 1535096.9 | Z9: 0 | AA9: Not Applicable | AB9: Quezon City | AC9: G. Bunag | AD9: Monthly | AE9: 66.01 | AF9: 0 | AG9: Not Applicable | AI9: =IF(F9<25,"18-24",IF(F9<35,"25-34",IF(F9<45,"35-44",IF(F9<55,"45-54",IF(F9<65,"55-64","65+"))))) -> 18-24 | AJ9: =YEAR(tbl_LoanData[[#This Row],[Application Date]]) -> 2023 | AK9: =TEXT(tbl_LoanData[[#This Row],[Application Date]],"MMMM") -> January | AL9: =DATE(YEAR(tbl_LoanData[[#This Row],[Application Date]]),MONTH(tbl_LoanData[[#This Row],[Application Date]]),1) -> 44927 | AM9: =IF(AND(tbl_LoanData[[#This Row],[Application Date]]>=EOMONTH(TODAY(),-1)+1,tbl_LoanData[[#This Row],[Application Date]]<=TODAY()),tbl_LoanData[[#This Row],[Loan Amount]],0) -> 0 | AN9: =tbl_LoanData[[#This Row],[Amount Paid]]-(Q9-X9) -> -1090500 | AO9: =IF(tbl_LoanData[[#This Row],[Application Status]]="Approved",1,0) -> 0 | AP9: =IF(AND(J9>=DATE(YEAR(TODAY()),MONTH(TODAY()),1),J9<=TODAY()),"Current MTD",IF(AND(J9>=EOMONTH(TODAY(),-2)+1,J9<=EOMONTH(TODAY(),-1)),"Previous MTD","")) | AQ9: =IF(AND(J9>=DATE(YEAR(TODAY()),MONTH(TODAY()),1),J9<=TODAY()),TEXT(DATE(YEAR(TODAY()),MONTH(TODAY()),1),"mmm d")&"–"&DAY(TODAY()),IF(AND(J9>=EOMONTH(TODAY(),-2)+1,J9<=EOMONTH(TODAY(),-1)),""&TEXT(EOMONTH(TODAY(),-2)+1,"mmm d")&"–"&DAY(TODAY()),""))
A10: LN-100348 | B10: CUS-200348 | C10: Kristine | D10: Gonzales | E10: Tolentino | F10: 52 | G10: Female | H10: Lapu-Lapu | I10: Region VII (Central Visayas) | J10: 44944 | K10: 44963 | L10: Truck | M10: Fuso | N10: Canter | O10: 2606000 | P10: 285400 | Q10: 2320600 | R10: 48 | S10: 11.85 | T10: 71261.76 | U10: Approved | V10: Active | W10: 2921732.2 | X10: 498832.24 | Y10: 3420564.4 | Z10: 30 | AA10: 1-30 Days | AB10: Manila | AC10: F. Lacson | AD10: Monthly | AE10: 89.05 | AF10: 1 | AG10: Low Risk | AH10: 19 | AI10: =IF(F10<25,"18-24",IF(F10<35,"25-34",IF(F10<45,"35-44",IF(F10<55,"45-54",IF(F10<65,"55-64","65+"))))) -> 45-54 | AJ10: =YEAR(tbl_LoanData[[#This Row],[Application Date]]) -> 2023 | AK10: =TEXT(tbl_LoanData[[#This Row],[Application Date]],"MMMM") -> January | AL10: =DATE(YEAR(tbl_LoanData[[#This Row],[Application Date]]),MONTH(tbl_LoanData[[#This Row],[Application Date]]),1) -> 44927 | AM10: =IF(AND(tbl_LoanData[[#This Row],[Application Date]]>=EOMONTH(TODAY(),-1)+1,tbl_LoanData[[#This Row],[Application Date]]<=TODAY()),tbl_LoanData[[#This Row],[Loan Amount]],0) -> 0 | AN10: =tbl_LoanData[[#This Row],[Amount Paid]]-(Q10-X10) -> 1099964.4 | AO10: =IF(tbl_LoanData[[#This Row],[Application Status]]="Approved",1,0) -> 1 | AP10: =IF(AND(J10>=DATE(YEAR(TODAY()),MONTH(TODAY()),1),J10<=TODAY()),"Current MTD",IF(AND(J10>=EOMONTH(TODAY(),-2)+1,J10<=EOMONTH(TODAY(),-1)),"Previous MTD","")) | AQ10: =IF(AND(J10>=DATE(YEAR(TODAY()),MONTH(TODAY()),1),J10<=TODAY()),TEXT(DATE(YEAR(TODAY()),MONTH(TODAY()),1),"mmm d")&"–"&DAY(TODAY()),IF(AND(J10>=EOMONTH(TODAY(),-2)+1,J10<=EOMONTH(TODAY(),-1)),""&TEXT(EOMONTH(TODAY(),-2)+1,"mmm d")&"–"&DAY(TODAY()),""))
A11: LN-100384 | B11: CUS-200384 | C11: Vincent | D11: Del Rosario | E11: Quiambao | F11: 35 | G11: Male | H11: Paranaque | I11: NCR | J11: 44938 | K11: 44958 | L11: Sedan | M11: Nissan | N11: Sylphy | O11: 1591000 | P11: 582300 | Q11: 1008700 | R11: 36 | S11: 14.16 | T11: 39922.1 | U11: Approved | V11: Defaulted | W11: 1237585.1 | X11: 199610.66 | Y11: 1437195.8 | Z11: 155 | AA11: Over 90 Days | AB11: Manila | AC11: A. Ramirez | AD11: Monthly | AE11: 63.4 | AF11: 5 | AG11: High Risk | AH11: 20 | AI11: =IF(F11<25,"18-24",IF(F11<35,"25-34",IF(F11<45,"35-44",IF(F11<55,"45-54",IF(F11<65,"55-64","65+"))))) -> 35-44 | AJ11: =YEAR(tbl_LoanData[[#This Row],[Application Date]]) -> 2023 | AK11: =TEXT(tbl_LoanData[[#This Row],[Application Date]],"MMMM") -> January | AL11: =DATE(YEAR(tbl_LoanData[[#This Row],[Application Date]]),MONTH(tbl_LoanData[[#This Row],[Application Date]]),1) -> 44927 | AM11: =IF(AND(tbl_LoanData[[#This Row],[Application Date]]>=EOMONTH(TODAY(),-1)+1,tbl_LoanData[[#This Row],[Application Date]]<=TODAY()),tbl_LoanData[[#This Row],[Loan Amount]],0) -> 0 | AN11: =tbl_LoanData[[#This Row],[Amount Paid]]-(Q11-X11) -> 428495.76 | AO11: =IF(tbl_LoanData[[#This Row],[Application Status]]="Approved",1,0) -> 1 | AP11: =IF(AND(J11>=DATE(YEAR(TODAY()),MONTH(TODAY()),1),J11<=TODAY()),"Current MTD",IF(AND(J11>=EOMONTH(TODAY(),-2)+1,J11<=EOMONTH(TODAY(),-1)),"Previous MTD","")) | AQ11: =IF(AND(J11>=DATE(YEAR(TODAY()),MONTH(TODAY()),1),J11<=TODAY()),TEXT(DATE(YEAR(TODAY()),MONTH(TODAY()),1),"mmm d")&"–"&DAY(TODAY()),IF(AND(J11>=EOMONTH(TODAY(),-2)+1,J11<=EOMONTH(TODAY(),-1)),""&TEXT(EOMONTH(TODAY(),-2)+1,"mmm d")&"–"&DAY(TODAY()),""))
A12: LN-100420 | B12: CUS-200420 | C12: Maria | D12: Cruz | E12: Aguilar | F12: 44 | G12: Female | H12: Mandaluyong | I12: NCR | J12: 44929 | K12: 44947 | L12: MPV/Van | M12: Mitsubishi | N12: Xpander | O12: 2123000 | P12: 618400 | Q12: 1504600 | R12: 36 | S12: 9.08 | T12: 53179.25 | U12: Approved | V12: Closed - Fully Paid | W12: 1914453 | X12: 0 | Y12: 1914453 | Z12: 0 | AA12: Current | AB12: Manila | AC12: C. Villareal | AD12: Monthly | AE12: 70.87 | AF12: 0 | AG12: Low Risk | AH12: 18 | AI12: =IF(F12<25,"18-24",IF(F12<35,"25-34",IF(F12<45,"35-44",IF(F12<55,"45-54",IF(F12<65,"55-64","65+"))))) -> 35-44 | AJ12: =YEAR(tbl_LoanData[[#This Row],[Application Date]]) -> 2023 | AK12: =TEXT(tbl_LoanData[[#This Row],[Application Date]],"MMMM") -> January | AL12: =DATE(YEAR(tbl_LoanData[[#This Row],[Application Date]]),MONTH(tbl_LoanData[[#This Row],[Application Date]]),1) -> 44927 | AM12: =IF(AND(tbl_LoanData[[#This Row],[Application Date]]>=EOMONTH(TODAY(),-1)+1,tbl_LoanData[[#This Row],[Application Date]]<=TODAY()),tbl_LoanData[[#This Row],[Loan Amount]],0) -> 0 | AN12: =tbl_LoanData[[#This Row],[Amount Paid]]-(Q12-X12) -> 409853.04 | AO12: =IF(tbl_LoanData[[#This Row],[Application Status]]="Approved",1,0) -> 1 | AP12: =IF(AND(J12>=DATE(YEAR(TODAY()),MONTH(TODAY()),1),J12<=TODAY()),"Current MTD",IF(AND(J12>=EOMONTH(TODAY(),-2)+1,J12<=EOMONTH(TODAY(),-1)),"Previous MTD","")) | AQ12: =IF(AND(J12>=DATE(YEAR(TODAY()),MONTH(TODAY()),1),J12<=TODAY()),TEXT(DATE(YEAR(TODAY()),MONTH(TODAY()),1),"mmm d")&"–"&DAY(TODAY()),IF(AND(J12>=EOMONTH(TODAY(),-2)+1,J12<=EOMONTH(TODAY(),-1)),""&TEXT(EOMONTH(TODAY(),-2)+1,"mmm d")&"–"&DAY(TODAY()),""))
A13: LN-100657 | B13: CUS-200657 | C13: Melchor | D13: Domingo | E13: Del Rosario | F13: 24 | G13: Male | H13: San Fernando (Pampanga) | I13: Region III (Central Luzon) | J13: 44944 | K13: 44949 | L13: Sedan | M13: Mitsubishi | N13: Mirage G4 | O13: 1411000 | P13: 410300 | Q13: 1000700 | R13: 48 | S13: 6.89 | T13: 26593.6 | U13: Approved | V13: Active | W13: 1116931.2 | X13: 159561.72 | Y13: 1276492.9 | Z13: 29 | AA13: 1-30 Days | AB13: Quezon City | AC13: I. Cabrera | AD13: Monthly | AE13: 70.92 | AF13: 1 | AG13: Low Risk | AH13: 5 | AI13: =IF(F13<25,"18-24",IF(F13<35,"25-34",IF(F13<45,"35-44",IF(F13<55,"45-54",IF(F13<65,"55-64","65+"))))) -> 18-24 | AJ13: =YEAR(tbl_LoanData[[#This Row],[Application Date]]) -> 2023 | AK13: =TEXT(tbl_LoanData[[#This Row],[Application Date]],"MMMM") -> January | AL13: =DATE(YEAR(tbl_LoanData[[#This Row],[Application Date]]),MONTH(tbl_LoanData[[#This Row],[Application Date]]),1) -> 44927 | AM13: =IF(AND(tbl_LoanData[[#This Row],[Application Date]]>=EOMONTH(TODAY(),-1)+1,tbl_LoanData[[#This Row],[Application Date]]<=TODAY()),tbl_LoanData[[#This Row],[Loan Amount]],0) -> 0 | AN13: =tbl_LoanData[[#This Row],[Amount Paid]]-(Q13-X13) -> 275792.92 | AO13: =IF(tbl_LoanData[[#This Row],[Application Status]]="Approved",1,0) -> 1 | AP13: =IF(AND(J13>=DATE(YEAR(TODAY()),MONTH(TODAY()),1),J13<=TODAY()),"Current MTD",IF(AND(J13>=EOMONTH(TODAY(),-2)+1,J13<=EOMONTH(TODAY(),-1)),"Previous MTD","")) | AQ13: =IF(AND(J13>=DATE(YEAR(TODAY()),MONTH(TODAY()),1),J13<=TODAY()),TEXT(DATE(YEAR(TODAY()),MONTH(TODAY()),1),"mmm d")&"–"&DAY(TODAY()),IF(AND(J13>=EOMONTH(TODAY(),-2)+1,J13<=EOMONTH(TODAY(),-1)),""&TEXT(EOMONTH(TODAY(),-2)+1,"mmm d")&"–"&DAY(TODAY()),""))
A14: LN-100714 | B14: CUS-200714 | C14: Marites | D14: Reyes | E14: Rosales | F14: 60 | G14: Female | H14: Vigan | I14: Region I (Ilocos Region) | J14: 44928 | L14: MPV/Van | M14: Honda | N14: Mobilio | O14: 1717000 | P14: 648000 | Q14: 1069000 | R14: 48 | S14: 12.92 | T14: 33780.4 | U14: Rejected | V14: Not Applicable | W14: 0 | X14: 0 | Y14: 1621459.2 | Z14: 0 | AA14: Not Applicable | AB14: Baguio | AC14: H. Isip | AD14: Monthly | AE14: 62.26 | AF14: 0 | AG14: Not Applicable | AI14: =IF(F14<25,"18-24",IF(F14<35,"25-34",IF(F14<45,"35-44",IF(F14<55,"45-54",IF(F14<65,"55-64","65+"))))) -> 55-64 | AJ14: =YEAR(tbl_LoanData[[#This Row],[Application Date]]) -> 2023 | AK14: =TEXT(tbl_LoanData[[#This Row],[Application Date]],"MMMM") -> January | AL14: =DATE(YEAR(tbl_LoanData[[#This Row],[Application Date]]),MONTH(tbl_LoanData[[#This Row],[Application Date]]),1) -> 44927 | AM14: =IF(AND(tbl_LoanData[[#This Row],[Application Date]]>=EOMONTH(TODAY(),-1)+1,tbl_LoanData[[#This Row],[Application Date]]<=TODAY()),tbl_LoanData[[#This Row],[Loan Amount]],0) -> 0 | AN14: =tbl_LoanData[[#This Row],[Amount Paid]]-(Q14-X14) -> -1069000 | AO14: =IF(tbl_LoanData[[#This Row],[Application Status]]="Approved",1,0) -> 0 | AP14: =IF(AND(J14>=DATE(YEAR(TODAY()),MONTH(TODAY()),1),J14<=TODAY()),"Current MTD",IF(AND(J14>=EOMONTH(TODAY(),-2)+1,J14<=EOMONTH(TODAY(),-1)),"Previous MTD","")) | AQ14: =IF(AND(J14>=DATE(YEAR(TODAY()),MONTH(TODAY()),1),J14<=TODAY()),TEXT(DATE(YEAR(TODAY()),MONTH(TODAY()),1),"mmm d")&"–"&DAY(TODAY()),IF(AND(J14>=EOMONTH(TODAY(),-2)+1,J14<=EOMONTH(TODAY(),-1)),""&TEXT(EOMONTH(TODAY(),-2)+1,"mmm d")&"–"&DAY(TODAY()),""))
A15: LN-100721 | B15: CUS-200721 | C15: Bienvenido | D15: Reyes | E15: Sarmiento | F15: 26 | G15: Male | H15: Davao City | I15: Region XI (Davao Region) | J15: 44928 | K15: 44938 | L15: Pickup | M15: Mitsubishi | N15: Strada | O15: 1761000 | P15: 429500 | Q15: 1331500 | R15: 24 | S15: 6.98 | T15: 63224.06 | U15: Approved | V15: Closed - Fully Paid | W15: 1517377.4 | X15: 0 | Y15: 1517377.4 | Z15: 0 | AA15: Current | AB15: Pampanga | AC15: F. Lacson | AD15: Monthly | AE15: 75.61 | AF15: 0 | AG15: Low Risk | AH15: 10 | AI15: =IF(F15<25,"18-24",IF(F15<35,"25-34",IF(F15<45,"35-44",IF(F15<55,"45-54",IF(F15<65,"55-64","65+"))))) -> 25-34 | AJ15: =YEAR(tbl_LoanData[[#This Row],[Application Date]]) -> 2023 | AK15: =TEXT(tbl_LoanData[[#This Row],[Application Date]],"MMMM") -> January | AL15: =DATE(YEAR(tbl_LoanData[[#This Row],[Application Date]]),MONTH(tbl_LoanData[[#This Row],[Application Date]]),1) -> 44927 | AM15: =IF(AND(tbl_LoanData[[#This Row],[Application Date]]>=EOMONTH(TODAY(),-1)+1,tbl_LoanData[[#This Row],[Application Date]]<=TODAY()),tbl_LoanData[[#This Row],[Loan Amount]],0) -> 0 | AN15: =tbl_LoanData[[#This Row],[Amount Paid]]-(Q15-X15) -> 185877.4 | AO15: =IF(tbl_LoanData[[#This Row],[Application Status]]="Approved",1,0) -> 1 | AP15: =IF(AND(J15>=DATE(YEAR(TODAY()),MONTH(TODAY()),1),J15<=TODAY()),"Current MTD",IF(AND(J15>=EOMONTH(TODAY(),-2)+1,J15<=EOMONTH(TODAY(),-1)),"Previous MTD","")) | AQ15: =IF(AND(J15>=DATE(YEAR(TODAY()),MONTH(TODAY()),1),J15<=TODAY()),TEXT(DATE(YEAR(TODAY()),MONTH(TODAY()),1),"mmm d")&"–"&DAY(TODAY()),IF(AND(J15>=EOMONTH(TODAY(),-2)+1,J15<=EOMONTH(TODAY(),-1)),""&TEXT(EOMONTH(TODAY(),-2)+1,"mmm d")&"–"&DAY(TODAY()),""))
A16: LN-100739 | B16: CUS-200739 | C16: Federico | D16: Ocampo | E16: Gonzales | F16: 34 | G16: Male | H16: Bacolod | I16: Region VI (Western Visayas) | J16: 44933 | K16: 44938 | L16: MPV/Van | M16: Honda | N16: Mobilio | O16: 1654000 | P16: 175600 | Q16: 1478400 | R16: 36 | S16: 14.61 | T16: 59066.19 | U16: Approved | V16: Closed - Fully Paid | W16: 2126382.7 | X16: 0 | Y16: 2126382.7 | Z16: 0 | AA16: Current | AB16: CDO | AC16: I. Cabrera | AD16: Monthly | AE16: 89.38 | AF16: 0 | AG16: Low Risk | AH16: 5 | AI16: =IF(F16<25,"18-24",IF(F16<35,"25-34",IF(F16<45,"35-44",IF(F16<55,"45-54",IF(F16<65,"55-64","65+"))))) -> 25-34 | AJ16: =YEAR(tbl_LoanData[[#This Row],[Application Date]]) -> 2023 | AK16: =TEXT(tbl_LoanData[[#This Row],[Application Date]],"MMMM") -> January | AL16: =DATE(YEAR(tbl_LoanData[[#This Row],[Application Date]]),MONTH(tbl_LoanData[[#This Row],[Application Date]]),1) -> 44927 | AM16: =IF(AND(tbl_LoanData[[#This Row],[Application Date]]>=EOMONTH(TODAY(),-1)+1,tbl_LoanData[[#This Row],[Application Date]]<=TODAY()),tbl_LoanData[[#This Row],[Loan Amount]],0) -> 0 | AN16: =tbl_LoanData[[#This Row],[Amount Paid]]-(Q16-X16) -> 647982.72 | AO16: =IF(tbl_LoanData[[#This Row],[Application Status]]="Approved",1,0) -> 1 | AP16: =IF(AND(J16>=DATE(YEAR(TODAY()),MONTH(TODAY()),1),J16<=TODAY()),"Current MTD",IF(AND(J16>=EOMONTH(TODAY(),-2)+1,J16<=EOMONTH(TODAY(),-1)),"Previous MTD","")) | AQ16: =IF(AND(J16>=DATE(YEAR(TODAY()),MONTH(TODAY()),1),J16<=TODAY()),TEXT(DATE(YEAR(TODAY()),MONTH(TODAY()),1),"mmm d")&"–"&DAY(TODAY()),IF(AND(J16>=EOMONTH(TODAY(),-2)+1,J16<=EOMONTH(TODAY(),-1)),""&TEXT(EOMONTH(TODAY(),-2)+1,"mmm d")&"–"&DAY(TODAY()),""))
A17: LN-100781 | B17: CUS-200781 | C17: Herminia | D17: Pascual | E17: Pascual | F17: 52 | G17: Female | H17: Cabanatuan | I17: Region III (Central Luzon) | J17: 44952 | L17: SUV | M17: Toyota | N17: Fortuner | O17: 2195000 | P17: 748600 | Q17: 1446400 | R17: 60 | S17: 6.79 | T17: 32290.88 | U17: Rejected | V17: Not Applicable | W17: 0 | X17: 0 | Y17: 1937452.8 | Z17: 0 | AA17: Not Applicable | AB17: Cebu | AC17: I. Cabrera | AD17: Monthly | AE17: 65.9 | AF17: 0 | AG17: Not Applicable | AI17: =IF(F17<25,"18-24",IF(F17<35,"25-34",IF(F17<45,"35-44",IF(F17<55,"45-54",IF(F17<65,"55-64","65+"))))) -> 45-54 | AJ17: =YEAR(tbl_LoanData[[#This Row],[Application Date]]) -> 2023 | AK17: =TEXT(tbl_LoanData[[#This Row],[Application Date]],"MMMM") -> January | AL17: =DATE(YEAR(tbl_LoanData[[#This Row],[Application Date]]),MONTH(tbl_LoanData[[#This Row],[Application Date]]),1) -> 44927 | AM17: =IF(AND(tbl_LoanData[[#This Row],[Application Date]]>=EOMONTH(TODAY(),-1)+1,tbl_LoanData[[#This Row],[Application Date]]<=TODAY()),tbl_LoanData[[#This Row],[Loan Amount]],0) -> 0 | AN17: =tbl_LoanData[[#This Row],[Amount Paid]]-(Q17-X17) -> -1446400 | AO17: =IF(tbl_LoanData[[#This Row],[Application Status]]="Approved",1,0) -> 0 | AP17: =IF(AND(J17>=DATE(YEAR(TODAY()),MONTH(TODAY()),1),J17<=TODAY()),"Current MTD",IF(AND(J17>=EOMONTH(TODAY(),-2)+1,J17<=EOMONTH(TODAY(),-1)),"Previous MTD","")) | AQ17: =IF(AND(J17>=DATE(YEAR(TODAY()),MONTH(TODAY()),1),J17<=TODAY()),TEXT(DATE(YEAR(TODAY()),MONTH(TODAY()),1),"mmm d")&"–"&DAY(TODAY()),IF(AND(J17>=EOMONTH(TODAY(),-2)+1,J17<=EOMONTH(TODAY(),-1)),""&TEXT(EOMONTH(TODAY(),-2)+1,"mmm d")&"–"&DAY(TODAY()),""))
A18: LN-100842 | B18: CUS-200842 | C18: Efren | D18: Bautista | E18: Pascual | F18: 30 | G18: Male | H18: Marikina | I18: NCR | J18: 44934 | L18: Truck | M18: Hino | N18: 500 Series | O18: 3675000 | P18: 815700 | Q18: 2859300 | R18: 60 | S18: 8.72 | T18: 68432.58 | U18: Rejected | V18: Not Applicable | W18: 0 | X18: 0 | Y18: 4105954.8 | Z18: 0 | AA18: Not Applicable | AB18: Cebu | AC18: D. Morales | AD18: Monthly | AE18: 77.8 | AF18: 0 | AG18: Not Applicable | AI18: =IF(F18<25,"18-24",IF(F18<35,"25-34",IF(F18<45,"35-44",IF(F18<55,"45-54",IF(F18<65,"55-64","65+"))))) -> 25-34 | AJ18: =YEAR(tbl_LoanData[[#This Row],[Application Date]]) -> 2023 | AK18: =TEXT(tbl_LoanData[[#This Row],[Application Date]],"MMMM") -> January | AL18: =DATE(YEAR(tbl_LoanData[[#This Row],[Application Date]]),MONTH(tbl_LoanData[[#This Row],[Application Date]]),1) -> 44927 | AM18: =IF(AND(tbl_LoanData[[#This Row],[Application Date]]>=EOMONTH(TODAY(),-1)+1,tbl_LoanData[[#This Row],[Application Date]]<=TODAY()),tbl_LoanData[[#This Row],[Loan Amount]],0) -> 0 | AN18: =tbl_LoanData[[#This Row],[Amount Paid]]-(Q18-X18) -> -2859300 | AO18: =IF(tbl_LoanData[[#This Row],[Application Status]]="Approved",1,0) -> 0 | AP18: =IF(AND(J18>=DATE(YEAR(TODAY()),MONTH(TODAY()),1),J18<=TODAY()),"Current MTD",IF(AND(J18>=EOMONTH(TODAY(),-2)+1,J18<=EOMONTH(TODAY(),-1)),"Previous MTD","")) | AQ18: =IF(AND(J18>=DATE(YEAR(TODAY()),MONTH(TODAY()),1),J18<=TODAY()),TEXT(DATE(YEAR(TODAY()),MONTH(TODAY()),1),"mmm d")&"–"&DAY(TODAY()),IF(AND(J18>=EOMONTH(TODAY(),-2)+1,J18<=EOMONTH(TODAY(),-1)),""&TEXT(EOMONTH(TODAY(),-2)+1,"mmm d")&"–"&DAY(TODAY()),""))
A19: LN-100871 | B19: CUS-200871 | C19: Danilo | D19: Gonzales | E19: Aquino | F19: 51 | G19: Male | H19: Lipa | I19: Region IV-A (CALABARZON) | J19: 44927 | K19: 44941 | L19: Pickup | M19: Ford | N19: Ranger | O19: 1808000 | P19: 303200 | Q19: 1504800 | R19: 36 | S19: 8.2 | T19: 52082.8 | U19: Approved | V19: Defaulted | W19: 1770815.2 | X19: 104165.6 | Y19: 1874980.8 | Z19: 60 | AA19: 31-60 Days | AB19: Iloilo | AC19: J. Espino | AD19: Monthly | AE19: 83.23 | AF19: 2 | AG19: Medium RIsk | AH19: 14 | AI19: =IF(F19<25,"18-24",IF(F19<35,"25-34",IF(F19<45,"35-44",IF(F19<55,"45-54",IF(F19<65,"55-64","65+"))))) -> 45-54 | AJ19: =YEAR(tbl_LoanData[[#This Row],[Application Date]]) -> 2023 | AK19: =TEXT(tbl_LoanData[[#This Row],[Application Date]],"MMMM") -> January | AL19: =DATE(YEAR(tbl_LoanData[[#This Row],[Application Date]]),MONTH(tbl_LoanData[[#This Row],[Application Date]]),1) -> 44927 | AM19: =IF(AND(tbl_LoanData[[#This Row],[Application Date]]>=EOMONTH(TODAY(),-1)+1,tbl_LoanData[[#This Row],[Application Date]]<=TODAY()),tbl_LoanData[[#This Row],[Loan Amount]],0) -> 0 | AN19: =tbl_LoanData[[#This Row],[Amount Paid]]-(Q19-X19) -> 370180.8 | AO19: =IF(tbl_LoanData[[#This Row],[Application Status]]="Approved",1,0) -> 1 | AP19: =IF(AND(J19>=DATE(YEAR(TODAY()),MONTH(TODAY()),1),J19<=TODAY()),"Current MTD",IF(AND(J19>=EOMONTH(TODAY(),-2)+1,J19<=EOMONTH(TODAY(),-1)),"Previous MTD","")) | AQ19: =IF(AND(J19>=DATE(YEAR(TODAY()),MONTH(TODAY()),1),J19<=TODAY()),TEXT(DATE(YEAR(TODAY()),MONTH(TODAY()),1),"mmm d")&"–"&DAY(TODAY()),IF(AND(J19>=EOMONTH(TODAY(),-2)+1,J19<=EOMONTH(TODAY(),-1)),""&TEXT(EOMONTH(TODAY(),-2)+1,"mmm d")&"–"&DAY(TODAY()),""))
A20: LN-100919 | B20: CUS-200919 | C20: Hazel | D20: Domingo | E20: Pascual | F20: 64 | G20: Female | H20: Cagayan de Oro | I20: Region X (Northern Mindanao) | J20: 44956 | L20: SUV | M20: Mitsubishi | N20: Xpander Cross | O20: 1292000 | P20: 486500 | Q20: 805500 | R20: 24 | S20: 10.17 | T20: 40389.11 | U20: Pending | V20: Not Applicable | W20: 0 | X20: 0 | Y20: 969338.7 | Z20: 0 | AA20: Not Applicable | AB20: Baguio | AC20: B. Santiago | AD20: Monthly | AE20: 62.35 | AF20: 0 | AG20: Not Applicable | AI20: =IF(F20<25,"18-24",IF(F20<35,"25-34",IF(F20<45,"35-44",IF(F20<55,"45-54",IF(F20<65,"55-64","65+"))))) -> 55-64 | AJ20: =YEAR(tbl_LoanData[[#This Row],[Application Date]]) -> 2023 | AK20: =TEXT(tbl_LoanData[[#This Row],[Application Date]],"MMMM") -> January | AL20: =DATE(YEAR(tbl_LoanData[[#This Row],[Application Date]]),MONTH(tbl_LoanData[[#This Row],[Application Date]]),1) -> 44927 | AM20: =IF(AND(tbl_LoanData[[#This Row],[Application Date]]>=EOMONTH(TODAY(),-1)+1,tbl_LoanData[[#This Row],[Application Date]]<=TODAY()),tbl_LoanData[[#This Row],[Loan Amount]],0) -> 0 | AN20: =tbl_LoanData[[#This Row],[Amount Paid]]-(Q20-X20) -> -805500 | AO20: =IF(tbl_LoanData[[#This Row],[Application Status]]="Approved",1,0) -> 0 | AP20: =IF(AND(J20>=DATE(YEAR(TODAY()),MONTH(TODAY()),1),J20<=TODAY()),"Current MTD",IF(AND(J20>=EOMONTH(TODAY(),-2)+1,J20<=EOMONTH(TODAY(),-1)),"Previous MTD","")) | AQ20: =IF(AND(J20>=DATE(YEAR(TODAY()),MONTH(TODAY()),1),J20<=TODAY()),TEXT(DATE(YEAR(TODAY()),MONTH(TODAY()),1),"mmm d")&"–"&DAY(TODAY()),IF(AND(J20>=EOMONTH(TODAY(),-2)+1,J20<=EOMONTH(TODAY(),-1)),""&TEXT(EOMONTH(TODAY(),-2)+1,"mmm d")&"–"&DAY(TODAY()),""))
A21: LN-100958 | B21: CUS-200958 | C21: Christian | D21: Cruz | E21: Cortez | F21: 48 | G21: Male | H21: General Santos | I21: Region XII (SOCCSKSARGEN) | J21: 44957 | K21: 44967 | L21: Pickup | M21: Nissan | N21: Navara | O21: 1807000 | P21: 414800 | Q21: 1392200 | R21: 36 | S21: 13.87 | T21: 54763.73 | U21: Approved | V21: Defaulted | W21: 1861966.8 | X21: 109527.6 | Y21: 1971494.4 | Z21: 62 | AA21: 61-90 Days | AB21: Iloilo | AC21: J. Espino | AD21: Monthly | AE21: 77.04 | AF21: 2 | AG21: High Risk | AH21: 10 | AI21: =IF(F21<25,"18-24",IF(F21<35,"25-34",IF(F21<45,"35-44",IF(F21<55,"45-54",IF(F21<65,"55-64","65+"))))) -> 45-54 | AJ21: =YEAR(tbl_LoanData[[#This Row],[Application Date]]) -> 2023 | AK21: =TEXT(tbl_LoanData[[#This Row],[Application Date]],"MMMM") -> January | AL21: =DATE(YEAR(tbl_LoanData[[#This Row],[Application Date]]),MONTH(tbl_LoanData[[#This Row],[Application Date]]),1) -> 44927 | AM21: =IF(AND(tbl_LoanData[[#This Row],[Application Date]]>=EOMONTH(TODAY(),-1)+1,tbl_LoanData[[#This Row],[Application Date]]<=TODAY()),tbl_LoanData[[#This Row],[Loan Amount]],0) -> 0 | AN21: =tbl_LoanData[[#This Row],[Amount Paid]]-(Q21-X21) -> 579294.42 | AO21: =IF(tbl_LoanData[[#This Row],[Application Status]]="Approved",1,0) -> 1 | AP21: =IF(AND(J21>=DATE(YEAR(TODAY()),MONTH(TODAY()),1),J21<=TODAY()),"Current MTD",IF(AND(J21>=EOMONTH(TODAY(),-2)+1,J21<=EOMONTH(TODAY(),-1)),"Previous MTD","")) | AQ21: =IF(AND(J21>=DATE(YEAR(TODAY()),MONTH(TODAY()),1),J21<=TODAY()),TEXT(DATE(YEAR(TODAY()),MONTH(TODAY()),1),"mmm d")&"–"&DAY(TODAY()),IF(AND(J21>=EOMONTH(TODAY(),-2)+1,J21<=EOMONTH(TODAY(),-1)),""&TEXT(EOMONTH(TODAY(),-2)+1,"mmm d")&"–"&DAY(TODAY()),""))
A22: LN-100977 | B22: CUS-200977 | C22: Efren | D22: Ramos | E22: Aguilar | F22: 39 | G22: Male | H22: Lucena | I22: Region IV-A (CALABARZON) | J22: 44934 | K22: 44953 | L22: Sedan | M22: Mitsubishi | N22: Mirage G4 | O22: 968000 | P22: 126100 | Q22: 841900 | R22: 48 | S22: 8.3 | T22: 23362.72 | U22: Approved | V22: Active | W22: 911146.08 | X22: 210264.72 | Y22: 1121410.8 | Z22: 128 | AA22: Over 90 Days | AB22: Iloilo | AC22: J. Espino | AD22: Monthly | AE22: 86.97 | AF22: 4 | AG22: High Risk | AH22: 19 | AI22: =IF(F22<25,"18-24",IF(F22<35,"25-34",IF(F22<45,"35-44",IF(F22<55,"45-54",IF(F22<65,"55-64","65+"))))) -> 35-44 | AJ22: =YEAR(tbl_LoanData[[#This Row],[Application Date]]) -> 2023 | AK22: =TEXT(tbl_LoanData[[#This Row],[Application Date]],"MMMM") -> January | AL22: =DATE(YEAR(tbl_LoanData[[#This Row],[Application Date]]),MONTH(tbl_LoanData[[#This Row],[Application Date]]),1) -> 44927 | AM22: =IF(AND(tbl_LoanData[[#This Row],[Application Date]]>=EOMONTH(TODAY(),-1)+1,tbl_LoanData[[#This Row],[Application Date]]<=TODAY()),tbl_LoanData[[#This Row],[Loan Amount]],0) -> 0 | AN22: =tbl_LoanData[[#This Row],[Amount Paid]]-(Q22-X22) -> 279510.8 | AO22: =IF(tbl_LoanData[[#This Row],[Application Status]]="Approved",1,0) -> 1 | AP22: =IF(AND(J22>=DATE(YEAR(TODAY()),MONTH(TODAY()),1),J22<=TODAY()),"Current MTD",IF(AND(J22>=EOMONTH(TODAY(),-2)+1,J22<=EOMONTH(TODAY(),-1)),"Previous MTD","")) | AQ22: =IF(AND(J22>=DATE(YEAR(TODAY()),MONTH(TODAY()),1),J22<=TODAY()),TEXT(DATE(YEAR(TODAY()),MONTH(TODAY()),1),"mmm d")&"–"&DAY(TODAY()),IF(AND(J22>=EOMONTH(TODAY(),-2)+1,J22<=EOMONTH(TODAY(),-1)),""&TEXT(EOMONTH(TODAY(),-2)+1,"mmm d")&"–"&DAY(TODAY()),""))
A23: LN-101017 | B23: CUS-201017 | C23: Camille | D23: Garcia | E23: Torres | F23: 62 | G23: Female | H23: Naga (Camarines Sur) | I23: Region V (Bicol Region) | J23: 44931 | K23: 44941 | L23: Sedan | M23: Honda | N23: Civic | O23: 999000 | P23: 341700 | Q23: 657300 | R23: 36 | S23: 5.26 | T23: 21139.5 | U23: Approved | V23: Defaulted | W23: 739882.5 | X23: 21139.44 | Y23: 761021.94 | Z23: 32 | AA23: 31-60 Days | AB23: Makati | AC23: D. Morales | AD23: Monthly | AE23: 65.8 | AF23: 1 | AG23: Medium RIsk | AH23: 10 | AI23: =IF(F23<25,"18-24",IF(F23<35,"25-34",IF(F23<45,"35-44",IF(F23<55,"45-54",IF(F23<65,"55-64","65+"))))) -> 55-64 | AJ23: =YEAR(tbl_LoanData[[#This Row],[Application Date]]) -> 2023 | AK23: =TEXT(tbl_LoanData[[#This Row],[Application Date]],"MMMM") -> January | AL23: =DATE(YEAR(tbl_LoanData[[#This Row],[Application Date]]),MONTH(tbl_LoanData[[#This Row],[Application Date]]),1) -> 44927 | AM23: =IF(AND(tbl_LoanData[[#This Row],[Application Date]]>=EOMONTH(TODAY(),-1)+1,tbl_LoanData[[#This Row],[Application Date]]<=TODAY()),tbl_LoanData[[#This Row],[Loan Amount]],0) -> 0 | AN23: =tbl_LoanData[[#This Row],[Amount Paid]]-(Q23-X23) -> 103721.94 | AO23: =IF(tbl_LoanData[[#This Row],[Application Status]]="Approved",1,0) -> 1 | AP23: =IF(AND(J23>=DATE(YEAR(TODAY()),MONTH(TODAY()),1),J23<=TODAY()),"Current MTD",IF(AND(J23>=EOMONTH(TODAY(),-2)+1,J23<=EOMONTH(TODAY(),-1)),"Previous MTD","")) | AQ23: =IF(AND(J23>=DATE(YEAR(TODAY()),MONTH(TODAY()),1),J23<=TODAY()),TEXT(DATE(YEAR(TODAY()),MONTH(TODAY()),1),"mmm d")&"–"&DAY(TODAY()),IF(AND(J23>=EOMONTH(TODAY(),-2)+1,J23<=EOMONTH(TODAY(),-1)),""&TEXT(EOMONTH(TODAY(),-2)+1,"mmm d")&"–"&DAY(TODAY()),""))
A24: LN-101054 | B24: CUS-201054 | C24: Reynaldo | D24: Domingo | E24: Santos | F24: 48 | G24: Male | H24: Cagayan de Oro | I24: Region X (Northern Mindanao) | J24: 44932 | K24: 44946 | L24: Sedan | M24: Hyundai | N24: Accent | O24: 1538000 | P24: 300900 | Q24: 1237100 | R24: 36 | S24: 8.26 | T24: 42879.26 | U24: Approved | V24: Closed - Fully Paid | W24: 1543653.4 | X24: 0 | Y24: 1543653.4 | Z24: 0 | AA24: Current | AB24: Baguio | AC24: F. Lacson | AD24: Monthly | AE24: 80.44 | AF24: 0 | AG24: Low Risk | AH24: 14 | AI24: =IF(F24<25,"18-24",IF(F24<35,"25-34",IF(F24<45,"35-44",IF(F24<55,"45-54",IF(F24<65,"55-64","65+"))))) -> 45-54 | AJ24: =YEAR(tbl_LoanData[[#This Row],[Application Date]]) -> 2023 | AK24: =TEXT(tbl_LoanData[[#This Row],[Application Date]],"MMMM") -> January | AL24: =DATE(YEAR(tbl_LoanData[[#This Row],[Application Date]]),MONTH(tbl_LoanData[[#This Row],[Application Date]]),1) -> 44927 | AM24: =IF(AND(tbl_LoanData[[#This Row],[Application Date]]>=EOMONTH(TODAY(),-1)+1,tbl_LoanData[[#This Row],[Application Date]]<=TODAY()),tbl_LoanData[[#This Row],[Loan Amount]],0) -> 0 | AN24: =tbl_LoanData[[#This Row],[Amount Paid]]-(Q24-X24) -> 306553.38 | AO24: =IF(tbl_LoanData[[#This Row],[Application Status]]="Approved",1,0) -> 1 | AP24: =IF(AND(J24>=DATE(YEAR(TODAY()),MONTH(TODAY()),1),J24<=TODAY()),"Current MTD",IF(AND(J24>=EOMONTH(TODAY(),-2)+1,J24<=EOMONTH(TODAY(),-1)),"Previous MTD","")) | AQ24: =IF(AND(J24>=DATE(YEAR(TODAY()),MONTH(TODAY()),1),J24<=TODAY()),TEXT(DATE(YEAR(TODAY()),MONTH(TODAY()),1),"mmm d")&"–"&DAY(TODAY()),IF(AND(J24>=EOMONTH(TODAY(),-2)+1,J24<=EOMONTH(TODAY(),-1)),""&TEXT(EOMONTH(TODAY(),-2)+1,"mmm d")&"–"&DAY(TODAY()),""))
A25: LN-101135 | B25: CUS-201135 | C25: Michael | D25: Ocampo | E25: Marquez | F25: 28 | G25: Male | H25: Antipolo | I25: Region IV-A (CALABARZON) | J25: 44952 | L25: Sedan | M25: Toyota | N25: Camry | O25: 1271000 | P25: 487200 | Q25: 783800 | R25: 48 | S25: 12.05 | T25: 24199.82 | U25: Rejected | V25: Not Applicable | W25: 0 | X25: 0 | Y25: 1161591.6 | Z25: 0 | AA25: Not Applicable | AB25: Baguio | AC25: F. Lacson | AD25: Monthly | AE25: 61.67 | AF25: 0 | AG25: Not Applicable | AI25: =IF(F25<25,"18-24",IF(F25<35,"25-34",IF(F25<45,"35-44",IF(F25<55,"45-54",IF(F25<65,"55-64","65+"))))) -> 25-34 | AJ25: =YEAR(tbl_LoanData[[#This Row],[Application Date]]) -> 2023 | AK25: =TEXT(tbl_LoanData[[#This Row],[Application Date]],"MMMM") -> January | AL25: =DATE(YEAR(tbl_LoanData[[#This Row],[Application Date]]),MONTH(tbl_LoanData[[#This Row],[Application Date]]),1) -> 44927 | AM25: =IF(AND(tbl_LoanData[[#This Row],[Application Date]]>=EOMONTH(TODAY(),-1)+1,tbl_LoanData[[#This Row],[Application Date]]<=TODAY()),tbl_LoanData[[#This Row],[Loan Amount]],0) -> 0 | AN25: =tbl_LoanData[[#This Row],[Amount Paid]]-(Q25-X25) -> -783800 | AO25: =IF(tbl_LoanData[[#This Row],[Application Status]]="Approved",1,0) -> 0 | AP25: =IF(AND(J25>=DATE(YEAR(TODAY()),MONTH(TODAY()),1),J25<=TODAY()),"Current MTD",IF(AND(J25>=EOMONTH(TODAY(),-2)+1,J25<=EOMONTH(TODAY(),-1)),"Previous MTD","")) | AQ25: =IF(AND(J25>=DATE(YEAR(TODAY()),MONTH(TODAY()),1),J25<=TODAY()),TEXT(DATE(YEAR(TODAY()),MONTH(TODAY()),1),"mmm d")&"–"&DAY(TODAY()),IF(AND(J25>=EOMONTH(TODAY(),-2)+1,J25<=EOMONTH(TODAY(),-1)),""&TEXT(EOMONTH(TODAY(),-2)+1,"mmm d")&"–"&DAY(TODAY()),""))
A26: LN-101243 | B26: CUS-201243 | C26: Angelo | D26: Rivera | E26: Rivera | F26: 63 | G26: Male | H26: Calamba | I26: Region IV-A (CALABARZON) | J26: 44953 | K26: 44963 | L26: SUV | M26: Kia | N26: Seltos | O26: 1524000 | P26: 601700 | Q26: 922300 | R26: 36 | S26: 5.31 | T26: 29700.62 | U26: Approved | V26: Closed - Fully Paid | W26: 1069222.4 | X26: 0 | Y26: 1069222.4 | Z26: 0 | AA26: Current | AB26: Quezon City | AC26: A. Ramirez | AD26: Monthly | AE26: 60.52 | AF26: 0 | AG26: Low Risk | AH26: 10 | AI26: =IF(F26<25,"18-24",IF(F26<35,"25-34",IF(F26<45,"35-44",IF(F26<55,"45-54",IF(F26<65,"55-64","65+"))))) -> 55-64 | AJ26: =YEAR(tbl_LoanData[[#This Row],[Application Date]]) -> 2023 | AK26: =TEXT(tbl_LoanData[[#This Row],[Application Date]],"MMMM") -> January | AL26: =DATE(YEAR(tbl_LoanData[[#This Row],[Application Date]]),MONTH(tbl_LoanData[[#This Row],[Application Date]]),1) -> 44927 | AM26: =IF(AND(tbl_LoanData[[#This Row],[Application Date]]>=EOMONTH(TODAY(),-1)+1,tbl_LoanData[[#This Row],[Application Date]]<=TODAY()),tbl_LoanData[[#This Row],[Loan Amount]],0) -> 0 | AN26: =tbl_LoanData[[#This Row],[Amount Paid]]-(Q26-X26) -> 146922.39 | AO26: =IF(tbl_LoanData[[#This Row],[Application Status]]="Approved",1,0) -> 1 | AP26: =IF(AND(J26>=DATE(YEAR(TODAY()),MONTH(TODAY()),1),J26<=TODAY()),"Current MTD",IF(AND(J26>=EOMONTH(TODAY(),-2)+1,J26<=EOMONTH(TODAY(),-1)),"Previous MTD","")) | AQ26: =IF(AND(J26>=DATE(YEAR(TODAY()),MONTH(TODAY()),1),J26<=TODAY()),TEXT(DATE(YEAR(TODAY()),MONTH(TODAY()),1),"mmm d")&"–"&DAY(TODAY()),IF(AND(J26>=EOMONTH(TODAY(),-2)+1,J26<=EOMONTH(TODAY(),-1)),""&TEXT(EOMONTH(TODAY(),-2)+1,"mmm d")&"–"&DAY(TODAY()),""))
A27: LN-101244 | B27: CUS-201244 | C27: Teodoro | D27: Aquino | E27: Gonzales | F27: 41 | G27: Male | H27: Bacolod | I27: Region VI (Western Visayas) | J27: 44956 | L27: MPV/Van | M27: Nissan | N27: Urvan | O27: 1336000 | P27: 226000 | Q27: 1110000 | R27: 12 | S27: 11.49 | T27: 103128.25 | U27: Rejected | V27: Not Applicable | W27: 0 | X27: 0 | Y27: 1237539 | Z27: 0 | AA27: Not Applicable | AB27: Manila | AC27: I. Cabrera | AD27: Monthly | AE27: 83.08 | AF27: 0 | AG27: Not Applicable | AI27: =IF(F27<25,"18-24",IF(F27<35,"25-34",IF(F27<45,"35-44",IF(F27<55,"45-54",IF(F27<65,"55-64","65+"))))) -> 35-44 | AJ27: =YEAR(tbl_LoanData[[#This Row],[Application Date]]) -> 2023 | AK27: =TEXT(tbl_LoanData[[#This Row],[Application Date]],"MMMM") -> January | AL27: =DATE(YEAR(tbl_LoanData[[#This Row],[Application Date]]),MONTH(tbl_LoanData[[#This Row],[Application Date]]),1) -> 44927 | AM27: =IF(AND(tbl_LoanData[[#This Row],[Application Date]]>=EOMONTH(TODAY(),-1)+1,tbl_LoanData[[#This Row],[Application Date]]<=TODAY()),tbl_LoanData[[#This Row],[Loan Amount]],0) -> 0 | AN27: =tbl_LoanData[[#This Row],[Amount Paid]]-(Q27-X27) -> -1110000 | AO27: =IF(tbl_LoanData[[#This Row],[Application Status]]="Approved",1,0) -> 0 | AP27: =IF(AND(J27>=DATE(YEAR(TODAY()),MONTH(TODAY()),1),J27<=TODAY()),"Current MTD",IF(AND(J27>=EOMONTH(TODAY(),-2)+1,J27<=EOMONTH(TODAY(),-1)),"Previous MTD","")) | AQ27: =IF(AND(J27>=DATE(YEAR(TODAY()),MONTH(TODAY()),1),J27<=TODAY()),TEXT(DATE(YEAR(TODAY()),MONTH(TODAY()),1),"mmm d")&"–"&DAY(TODAY()),IF(AND(J27>=EOMONTH(TODAY(),-2)+1,J27<=EOMONTH(TODAY(),-1)),""&TEXT(EOMONTH(TODAY(),-2)+1,"mmm d")&"–"&DAY(TODAY()),""))
A28: LN-101267 | B28: CUS-201267 | C28: Bea | D28: Salazar | E28: Umali | F28: 54 | G28: Female | H28: Naga (Camarines Sur) | I28: Region V (Bicol Region) | J28: 44957 | L28: MPV/Van | M28: Toyota | N28: Avanza | O28: 973000 | P28: 195700 | Q28: 777300 | R28: 24 | S28: 7.21 | T28: 37057.78 | U28: Rejected | V28: Not Applicable | W28: 0 | X28: 0 | Y28: 889386.66 | Z28: 0 | AA28: Not Applicable | AB28: Manila | AC28: A. Ramirez | AD28: Monthly | AE28: 79.89 | AF28: 0 | AG28: Not Applicable | AI28: =IF(F28<25,"18-24",IF(F28<35,"25-34",IF(F28<45,"35-44",IF(F28<55,"45-54",IF(F28<65,"55-64","65+"))))) -> 45-54 | AJ28: =YEAR(tbl_LoanData[[#This Row],[Application Date]]) -> 2023 | AK28: =TEXT(tbl_LoanData[[#This Row],[Application Date]],"MMMM") -> January | AL28: =DATE(YEAR(tbl_LoanData[[#This Row],[Application Date]]),MONTH(tbl_LoanData[[#This Row],[Application Date]]),1) -> 44927 | AM28: =IF(AND(tbl_LoanData[[#This Row],[Application Date]]>=EOMONTH(TODAY(),-1)+1,tbl_LoanData[[#This Row],[Application Date]]<=TODAY()),tbl_LoanData[[#This Row],[Loan Amount]],0) -> 0 | AN28: =tbl_LoanData[[#This Row],[Amount Paid]]-(Q28-X28) -> -777300 | AO28: =IF(tbl_LoanData[[#This Row],[Application Status]]="Approved",1,0) -> 0 | AP28: =IF(AND(J28>=DATE(YEAR(TODAY()),MONTH(TODAY()),1),J28<=TODAY()),"Current MTD",IF(AND(J28>=EOMONTH(TODAY(),-2)+1,J28<=EOMONTH(TODAY(),-1)),"Previous MTD","")) | AQ28: =IF(AND(J28>=DATE(YEAR(TODAY()),MONTH(TODAY()),1),J28<=TODAY()),TEXT(DATE(YEAR(TODAY()),MONTH(TODAY()),1),"mmm d")&"–"&DAY(TODAY()),IF(AND(J28>=EOMONTH(TODAY(),-2)+1,J28<=EOMONTH(TODAY(),-1)),""&TEXT(EOMONTH(TODAY(),-2)+1,"mmm d")&"–"&DAY(TODAY()),""))
A29: LN-101285 | B29: CUS-201285 | C29: Marites | D29: Del Rosario | E29: Salazar | F29: 41 | G29: Female | H29: Angeles City | I29: Region III (Central Luzon) | J29: 44942 | K29: 44955 | L29: SUV | M29: Hyundai | N29: Tucson | O29: 1893000 | P29: 421700 | Q29: 1471300 | R29: 24 | S29: 5.79 | T29: 68403.19 | U29: Approved | V29: Closed - Fully Paid | W29: 1641676.5 | X29: 0 | Y29: 1641676.5 | Z29: 0 | AA29: Current | AB29: Baguio | AC29: D. Morales | AD29: Monthly | AE29: 77.72 | AF29: 0 | AG29: Low Risk | AH29: 13 | AI29: =IF(F29<25,"18-24",IF(F29<35,"25-34",IF(F29<45,"35-44",IF(F29<55,"45-54",IF(F29<65,"55-64","65+"))))) -> 35-44 | AJ29: =YEAR(tbl_LoanData[[#This Row],[Application Date]]) -> 2023 | AK29: =TEXT(tbl_LoanData[[#This Row],[Application Date]],"MMMM") -> January | AL29: =DATE(YEAR(tbl_LoanData[[#This Row],[Application Date]]),MONTH(tbl_LoanData[[#This Row],[Application Date]]),1) -> 44927 | AM29: =IF(AND(tbl_LoanData[[#This Row],[Application Date]]>=EOMONTH(TODAY(),-1)+1,tbl_LoanData[[#This Row],[Application Date]]<=TODAY()),tbl_LoanData[[#This Row],[Loan Amount]],0) -> 0 | AN29: =tbl_LoanData[[#This Row],[Amount Paid]]-(Q29-X29) -> 170376.54 | AO29: =IF(tbl_LoanData[[#This Row],[Application Status]]="Approved",1,0) -> 1 | AP29: =IF(AND(J29>=DATE(YEAR(TODAY()),MONTH(TODAY()),1),J29<=TODAY()),"Current MTD",IF(AND(J29>=EOMONTH(TODAY(),-2)+1,J29<=EOMONTH(TODAY(),-1)),"Previous MTD","")) | AQ29: =IF(AND(J29>=DATE(YEAR(TODAY()),MONTH(TODAY()),1),J29<=TODAY()),TEXT(DATE(YEAR(TODAY()),MONTH(TODAY()),1),"mmm d")&"–"&DAY(TODAY()),IF(AND(J29>=EOMONTH(TODAY(),-2)+1,J29<=EOMONTH(TODAY(),-1)),""&TEXT(EOMONTH(TODAY(),-2)+1,"mmm d")&"–"&DAY(TODAY()),""))
A30: LN-101358 | B30: CUS-201358 | C30: Marites | D30: Reyes | E30: Sarmiento | F30: 51 | G30: Female | H30: Cavite City | I30: Region IV-A (CALABARZON) | J30: 44934 | K30: 44943 | L30: Sedan | M30: Nissan | N30: Sylphy | O30: 887000 | P30: 238300 | Q30: 648700 | R30: 36 | S30: 6.03 | T30: 21279.16 | U30: Approved | V30: Closed - Fully Paid | W30: 766049.83 | X30: 0 | Y30: 766049.83 | Z30: 0 | AA30: Current | AB30: Pampanga | AC30: E. Ferrer | AD30: Monthly | AE30: 73.13 | AF30: 0 | AG30: Low Risk | AH30: 9 | AI30: =IF(F30<25,"18-24",IF(F30<35,"25-34",IF(F30<45,"35-44",IF(F30<55,"45-54",IF(F30<65,"55-64","65+"))))) -> 45-54 | AJ30: =YEAR(tbl_LoanData[[#This Row],[Application Date]]) -> 2023 | AK30: =TEXT(tbl_LoanData[[#This Row],[Application Date]],"MMMM") -> January | AL30: =DATE(YEAR(tbl_LoanData[[#This Row],[Application Date]]),MONTH(tbl_LoanData[[#This Row],[Application Date]]),1) -> 44927 | AM30: =IF(AND(tbl_LoanData[[#This Row],[Application Date]]>=EOMONTH(TODAY(),-1)+1,tbl_LoanData[[#This Row],[Application Date]]<=TODAY()),tbl_LoanData[[#This Row],[Loan Amount]],0) -> 0 | AN30: =tbl_LoanData[[#This Row],[Amount Paid]]-(Q30-X30) -> 117349.83 | AO30: =IF(tbl_LoanData[[#This Row],[Application Status]]="Approved",1,0) -> 1 | AP30: =IF(AND(J30>=DATE(YEAR(TODAY()),MONTH(TODAY()),1),J30<=TODAY()),"Current MTD",IF(AND(J30>=EOMONTH(TODAY(),-2)+1,J30<=EOMONTH(TODAY(),-1)),"Previous MTD","")) | AQ30: =IF(AND(J30>=DATE(YEAR(TODAY()),MONTH(TODAY()),1),J30<=TODAY()),TEXT(DATE(YEAR(TODAY()),MONTH(TODAY()),1),"mmm d")&"–"&DAY(TODAY()),IF(AND(J30>=EOMONTH(TODAY(),-2)+1,J30<=EOMONTH(TODAY(),-1)),""&TEXT(EOMONTH(TODAY(),-2)+1,"mmm d")&"–"&DAY(TODAY()),""))
A31: LN-101376 | B31: CUS-201376 | C31: Fe | D31: Castillo | E31: Umali | F31: 28 | G31: Female | H31: Olongapo | I31: Region III (Central Luzon) | J31: 44946 | L31: Sedan | M31: Nissan | N31: Almera | O31: 1500000 | P31: 476500 | Q31: 1023500 | R31: 48 | S31: 10.45 | T31: 30235.9 | U31: Rejected | V31: Not Applicable | W31: 0 | X31: 0 | Y31: 1451323 | Z31: 0 | AA31: Not Applicable | AB31: Cebu | AC31: J. Espino | AD31: Monthly | AE31: 68.23 | AF31: 0 | AG31: Not Applicable | AI31: =IF(F31<25,"18-24",IF(F31<35,"25-34",IF(F31<45,"35-44",IF(F31<55,"45-54",IF(F31<65,"55-64","65+"))))) -> 25-34 | AJ31: =YEAR(tbl_LoanData[[#This Row],[Application Date]]) -> 2023 | AK31: =TEXT(tbl_LoanData[[#This Row],[Application Date]],"MMMM") -> January | AL31: =DATE(YEAR(tbl_LoanData[[#This Row],[Application Date]]),MONTH(tbl_LoanData[[#This Row],[Application Date]]),1) -> 44927 | AM31: =IF(AND(tbl_LoanData[[#This Row],[Application Date]]>=EOMONTH(TODAY(),-1)+1,tbl_LoanData[[#This Row],[Application Date]]<=TODAY()),tbl_LoanData[[#This Row],[Loan Amount]],0) -> 0 | AN31: =tbl_LoanData[[#This Row],[Amount Paid]]-(Q31-X31) -> -1023500 | AO31: =IF(tbl_LoanData[[#This Row],[Application Status]]="Approved",1,0) -> 0 | AP31: =IF(AND(J31>=DATE(YEAR(TODAY()),MONTH(TODAY()),1),J31<=TODAY()),"Current MTD",IF(AND(J31>=EOMONTH(TODAY(),-2)+1,J31<=EOMONTH(TODAY(),-1)),"Previous MTD","")) | AQ31: =IF(AND(J31>=DATE(YEAR(TODAY()),MONTH(TODAY()),1),J31<=TODAY()),TEXT(DATE(YEAR(TODAY()),MONTH(TODAY()),1),"mmm d")&"–"&DAY(TODAY()),IF(AND(J31>=EOMONTH(TODAY(),-2)+1,J31<=EOMONTH(TODAY(),-1)),""&TEXT(EOMONTH(TODAY(),-2)+1,"mmm d")&"–"&DAY(TODAY()),""))
A32: LN-101676 | B32: CUS-201676 | C32: Teresa | D32: Cruz | E32: Panganiban | F32: 61 | G32: Female | H32: San Fernando (Pampanga) | I32: Region III (Central Luzon) | J32: 44951 | K32: 44963 | L32: Sedan | M32: Honda | N32: City | O32: 1259000 | P32: 158400 | Q32: 1100600 | R32: 24 | S32: 12.09 | T32: 56946.88 | U32: Approved | V32: Closed - Fully Paid | W32: 1366725.1 | X32: 0 | Y32: 1366725.1 | Z32: 0 | AA32: Current | AB32: Manila | AC32: C. Villareal | AD32: Monthly | AE32: 87.42 | AF32: 0 | AG32: Low Risk | AH32: 12 | AI32: =IF(F32<25,"18-24",IF(F32<35,"25-34",IF(F32<45,"35-44",IF(F32<55,"45-54",IF(F32<65,"55-64","65+"))))) -> 55-64 | AJ32: =YEAR(tbl_LoanData[[#This Row],[Application Date]]) -> 2023 | AK32: =TEXT(tbl_LoanData[[#This Row],[Application Date]],"MMMM") -> January | AL32: =DATE(YEAR(tbl_LoanData[[#This Row],[Application Date]]),MONTH(tbl_LoanData[[#This Row],[Application Date]]),1) -> 44927 | AM32: =IF(AND(tbl_LoanData[[#This Row],[Application Date]]>=EOMONTH(TODAY(),-1)+1,tbl_LoanData[[#This Row],[Application Date]]<=TODAY()),tbl_LoanData[[#This Row],[Loan Amount]],0) -> 0 | AN32: =tbl_LoanData[[#This Row],[Amount Paid]]-(Q32-X32) -> 266125.08 | AO32: =IF(tbl_LoanData[[#This Row],[Application Status]]="Approved",1,0) -> 1 | AP32: =IF(AND(J32>=DATE(YEAR(TODAY()),MONTH(TODAY()),1),J32<=TODAY()),"Current MTD",IF(AND(J32>=EOMONTH(TODAY(),-2)+1,J32<=EOMONTH(TODAY(),-1)),"Previous MTD","")) | AQ32: =IF(AND(J32>=DATE(YEAR(TODAY()),MONTH(TODAY()),1),J32<=TODAY()),TEXT(DATE(YEAR(TODAY()),MONTH(TODAY()),1),"mmm d")&"–"&DAY(TODAY()),IF(AND(J32>=EOMONTH(TODAY(),-2)+1,J32<=EOMONTH(TODAY(),-1)),""&TEXT(EOMONTH(TODAY(),-2)+1,"mmm d")&"–"&DAY(TODAY()),""))
